<?xml version="1.0"?>

<robot name="my_robot">
  <material name="blue">
    <color rgba="0.1 0.1 0.8 0.9"/>
  </material>
  <material name="gray">
    <color rgba="0.8 0.8 0.8 0.9"/>
  </material>
  <link name="base_link">
    <visual>
      <geometry>
        <!-- 长宽高 -->
        <box size="0.6 0.4 0.2"/>
      </geometry>
      <origin xyz="0 0 0.1" rpy="0 0 0"/>
      <material name="blue"/>
    </visual>
  </link>
  <link name="right_wheel_link">
    <visual>
      <geometry>
        <cylinder radius="0.1" length="0.05"/>
      </geometry>
      <origin xyz="0 0 0" rpy="1.57 0 0"/>
      <material name="gray"/>
    </visual>
  </link>
  <joint name="base_right_wheel_joint" type="continuous">
    <parent link="base_link"/>
    <child link="right_wheel_link"/>
    <origin xyz="-0.15 -0.225 0" rpy="0 0 0"/>
    <axis xyz="0 1 0"/>
  </joint>
  <link name="left_wheel_link">
    <visual>
      <geometry>
        <cylinder radius="0.1" length="0.05"/>
      </geometry>
      <origin xyz="0 0 0" rpy="1.57 0 0"/>
      <material name="gray"/>
    </visual>
  </link>
  <joint name="base_left_wheel_joint" type="continuous">
    <parent link="base_link"/>
    <child link="left_wheel_link"/>
    <origin xyz="-0.15 0.225 0" rpy="0 0 0"/>
    <axis xyz="0 1 0"/>
  </joint>
  <link name="caster_wheel_link">
    <visual>
      <geometry>
        <sphere radius="0.05"/>
      </geometry>
      <origin xyz="0 0 0" rpy="1.57 0 0"/>
      <material name="gray"/>
    </visual>
  </link> 
  <joint name="base_caster_wheel_joint" type="fixed">
    <parent link="base_link"/>
    <child link="caster_wheel_link"/>
    <origin xyz="0.15 0 0" rpy="0 0 0"/>
  </joint>
</robot>
<!--ros2 launch urdf_tutorial display.launch.py model:=/home/yinkangan/Desktop/ros_practise/src/my_robot.urdf-->
